Workbook

Sheet Questions
A1: S.N | B1: Questionnaire | C1: Bifurcation | D1: Value | E1: Placeholder | F1: Dummy
A2: 1 | B2: सहकारीको नाम के हो?(What is the name of the cooperative?) | C2: coop_name | E2: ABC Cooperative
A3: 2 | B3: सहकारी कुन मोडेलमा चलिरहेको छ? (A / B)(Which model does the cooperative operate under?) | C3: model_type | E3: Milk Collection Only | F3: Milk Collection Only
A4: 3 | B4: सहकारी ऋण नयाँ हो कि पहिलेबाट छ?(Is the loan new or existing?) | C4: is_existing | E4: New | F4: Existing
A5: 4 | B5: सहकारी कति वर्षदेखि सञ्चालनमा छ?(How many years has the cooperative been operating?) | C5: years_operation | E5: 10 | F5: 10
A6: 5 | B6: सहकारीको कार्यालय कहाँ छ?(Where is the cooperative office located?) | C6: office_location | E6: KTM | F6: KTM
A7: 6 | B7: हाल चालु ऋणको बाँकी रकम कति छ?(What is the outstanding amount of the existing loan?) | C7: existing_loan_amt | E7: 1500000 | F7: 1500000
A8: 7 | B8: नयाँ प्रस्तावित ऋण रकम कति हो?(What is the proposed new loan amount?) | C8: proposed_loan_amt | E8: 200000 | F8: 200000
A9: 8 | B9: जम्मा ऋण (पुरानो + नयाँ) कति हुन्छ?(What will be the total loan (existing + new)?) | C9: Total Loan | E9: =E7+E8 -> 1700000 | F9: =F7+F8 -> 1700000
A10: 9 | B10: ऋणको ब्याजदर कति प्रतिशत छ?(What is the interest rate (%)?) | C10: interest_rate | E10: 12 | F10: 12
A11: 10 | B11: ऋण तिर्ने अवधि कति महिना हो?(What is the loan tenure (in months)?) | C11: loan_tenure_months | E11: 60 | F11: 60
A12: 11 | B12: किस्ताको भुक्तानी आवृत्ति के हो? (महिना / त्रैमासिक आदि)(What is the installment frequency (monthly/quarterly etc.)?) | C12: repayment_frequency | E12: Monthly | F12: Monthly
A13: 12 | B13: दूध बिक्रीबाट कति आम्दानी हुन्छ?(Income from milk sales?) | C13: milk_sales | E13: 28000000 | F13: 28000000
A14: 13 | B14: अन्य उत्पादन बिक्रीबाट कति आम्दानी हुन्छ?(Income from other product sales?) | C14: product_sales | E14: 1800000 | F14: 1800000
A15: 14 | B15: अन्य आम्दानी कति छ?(Other income amount?) | C15: other_sales | E15: 200000 | F15: 200000
A16: 15 | B16: कुल बिक्री कति छ?(Total sales?) | C16: Total Sales | E16: =E13+E14+E15 -> 30000000 | F16: =F13+F14+F15 -> 30000000
A17: 16 | B17: अनुदानबाट कति आम्दानी भएको छ?(Income from grants/subsidies?) | C17: grant_income | E17: 500000 | F17: 500000
A18: 17 | B18: Total Revenue (कुल आम्दानी) | C18: Total_Revenue | E18: =E17+E16 -> 30500000 | F18: =F17+F16 -> 30500000
A19: 18 | B19: बैंक मार्फत भएको बिक्री कति छ?(Sales received through bank?) | C19: bank_sales | E19: 15000000 | F19: 15000000
A20: 19 | B20: जम्मा खरिदकर्ता संख्या कति छ?(Total number of buyers?) | C20: total_number_of_buyers | E20: 300 | F20: 300
A21: 20 | B21: शीर्ष ५ खरिदकर्ताबाट कति बिक्री हुन्छ?(Sales from top 5 buyers?) | C21: top5_buyers_sales | E21: 8000000 | F21: 8000000
A22: 21 | B22: सबैभन्दा ठूलो एक जना खरिदकर्ताबाट कति बिक्री हुन्छ?(Sales from largest single buyer?) | C22: largest_buyer_sales | E22: 2000000 | F22: 2000000
A23: 22 | B23: सरकारी निकायलाई कति बिक्री हुन्छ?(Sales to government entities?) | C23: gov_buyer_sales | E23: 16000000 | F23: 16000000
A24: 23 | B24: कति सरकारी निकायलाई बिक्री हुन्छ?No of government entities buyer?) | C24: no_govt_buyers | E24: 120 | F24: 120
A25: 24 | B25: ठूला निजी डेरीलाई कति बिक्री हुन्छ?(Sales to large private dairies?) | C25: large_private_buyer_sales | E25: 4000000 | F25: 4000000
A26: 25 | B26: कति निजी डेरीलाई बिक्री हुन्छ?(No. of large/private sector buyers?) | C26: no_private_sector_buyer | E26: 30 | F26: 30
A27: 26 | B27: साना वा अनिश्चित खरिदकर्तालाई कति बिक्री हुन्छ?(Sales to small/unreliable buyers?) | C27: small_buyer_sales | E27: 8000000 | F27: 8000000
A28: 27 | B28: कति साना वा अनिश्चित खरिदकर्तालाई बिक्री हुन्छ?(No. of small/unreliable buyers?) | C28: no_small_buyer_sales | E28: 150 | F28: 150
A29: 28 | B29: खरिदकर्ताले भुक्तानी गर्न औसत कति दिन लिन्छन्?(Average collection period (days)?) | C29: avg_payment_days_buyers | E29: 35 | F29: 35
A30: 29 | B30: कच्चा दूध किन्न कति खर्च हुन्छ?(Cost of raw milk purchase?) | C30: raw_milk_purchase_cost | E30: 12000000 | F30: 12000000
A31: 30 | B31: शीर्ष ५ खरिदकर्ताको हिस्सा कति प्रतिशत छ?(% share of top 5 buyers?) | C31: top5_buyer_share_percent | E31: =(E21/E16) -> 0.26666667 | F31: =(F21/F16) -> 0.26666667
A32: 31 | B32: सबैभन्दा ठूलो खरिदकर्ताको हिस्सा कति प्रतिशत छ?(% share of largest buyer?) | C32: largest_buyer_share_percent | E32: =(E22/E16) -> 0.066666667 | F32: =(F22/F16) -> 0.066666667
A33: 32 | B33: कति बिक्री करार (Contract) मा छ?(no. of Buyers under contract?) | C33: contract_coverage | E33: 200 | F33: 200
A34: 33 | B34: प्रशोधन खर्च कति हुन्छ?(Processing cost?) | C34: processing_cost | E34: 2000000 | F34: 2000000
A35: 34 | B35: प्याकेजिङ खर्च कति हुन्छ?(Packaging cost?) | C35: packaging_cost | E35: 1000000 | F35: 1000000
A36: 35 | B36: ढुवानी खर्च कति हुन्छ?(Transportation cost?) | C36: transport_cost | E36: 500000 | F36: 500000
A37: 36 | B37: अन्य उत्पादन खर्च (Other Processign Cost?) | C37: other_processing_cost | E37: 200000 | F37: 200000
A38: 37 | B38: तलब खर्च कति छ?(Salary expense?) | C38: salary_expense | E38: 2500000 | F38: 2500000
A39: 38 | B39: प्रशासनिक खर्च कति छ?(Administrative expense?) | C39: admin_expense | E39: 1500000 | F39: 1500000
A40: 39 | B40: बिजुली खर्च कति छ?(Electricity expense?) | C40: electricity_expense | E40: 200000 | F40: 200000
...

Sheet Data
A1: SN | C1: Input Type | D1: Value | E1: Placeholder
A2: 1 | B2: Coop Name,सहकारीको नाम | C2: Text | D2: =Questions!D2 | E2: =Questions!E2 -> ABC Cooperative
A3: 2 | B3: Model Type,मोडलको प्रकार | C3: Dropdown | D3: =Questions!D3 | E3: =Questions!E3 -> Milk Collection Only
A4: 3 | B4: New / Existing,नयाँ / पहिलेबाट सञ्चालनमा रहेको | C4: Dropdown | D4: =Questions!D4 | E4: =Questions!E4 -> New
A5: 4 | B5: Existing Loan Amount (NPR),हाल चलिरहेको ऋण रकम (रु) | C5: Number | D5: =Questions!D7 | E5: =Questions!E7 -> 1500000
A6: 5 | B6: Proposed Loan Amount (NPR),प्रस्तावित ऋण रकम (रु) | C6: Number | D6: =Questions!D8 | E6: =Questions!E8 -> 200000
A7: 6 | B7: Total Revenue (NPR),कुल आम्दानी (रु) | C7: Number | D7: =Questions!D18 | E7: =Questions!E18 -> 30500000
A8: 7 | B8: EBITDA (NPR),संचालनबाट भएको आम्दानी (रु) | C8: Number | D8: =Questions!D18-SUM(Questions!D34:D37)-Questions!D45 -> 0 | E8: =Questions!E18-SUM(Questions!E34:E37)-Questions!E45 -> 21600000
A9: 8 | B9: Principal Repayment (NPR),मूलधन भुक्तानी रकम (रु) | C9: Number | D9: =Questions!D68 | E9: =Questions!E68 -> 500000
A10: 9 | B10: Interest (NPR),ब्याज रकम (रु) | C10: Number | D10: =Questions!D9*Questions!D10 -> 0 | E10: =Questions!E9*Questions!E10 -> 20400000
A11: 10 | B11: Total Assets (NPR),कुल सम्पत्ति (रु) | C11: Number | D11: =Questions!D56+Questions!D63 -> 0 | E11: =Questions!E56+Questions!E63 -> 31000000
A12: 11 | B12: Total Liabilities (NPR),कुल दायित्व (रु) | C12: Number | D12: =Questions!D69+Questions!D72 -> 0 | E12: =Questions!E69+Questions!E72 -> 6000000
A13: 12 | B13: Current Assets (NPR),चालु सम्पत्ति (रु) | C13: Number | D13: =Questions!D56 | E13: =Questions!E56 -> 15000000
A14: 13 | B14: Current Liabilities (NPR),चालु दायित्व (रु) | C14: Number | D14: =Questions!D69 | E14: =Questions!E69 -> 4500000
A15: 14 | B15: Total Debt (NPR),कुल ऋण (रु) | C15: Number | D15: =Questions!D66+Questions!D70 -> 0 | E15: =Questions!E66+Questions!E70 -> 3000000
A16: 15 | B16: Equity (NPR),पूँजी / इक्विटी (रु) | C16: Number | D16: =Questions!D77 | E16: =Questions!E77 -> 5500000
A17: 16 | B17: Grant Income (NPR),अनुदानबाट प्राप्त आम्दानी (रु) | C17: Number | D17: =Questions!D17 | E17: =Questions!E17 -> 500000
A18: 17 | B18: Total Operating Expenses (NPR),कुल सञ्चालन खर्च (रु) | C18: Number | D18: =Questions!D45 | E18: =Questions!E45 -> 5200000
A19: 18 | B19: Avg Inventory (NPR),औसत भण्डारण मूल्य (रु) | C19: Number | D19: =Questions!D53 | E19: =Questions!E53 -> 5500000
A20: 19 | B20: COGS (NPR),लागत (रु) | C20: Number | D20: =SUM(Questions!D34:D37) -> 0 | E20: =SUM(Questions!E34:E37) -> 3700000
A21: 20 | B21: Accounts Receivable (NPR),प्राप्त रकम (रु) | C21: Number | D21: =Questions!D52 | E21: =Questions!E52 -> 3500000
A22: 21 | B22: Avg Monthly Milk (Liters),मासिक औसत दूध सङ्कलन (लिटर) | C22: Number | D22: =Questions!D82 | E22: =Questions!E82 -> 24166.667
A23: 22 | B23: Lowest Monthly Milk (Liters),सबैभन्दा कम मासिक दूध सङ्कलन (लिटर) | C23: Number | D23: =Questions!D83 | E23: =Questions!E83 -> 20000
A24: 23 | B24: Total Milk Collected (Liters),कुल सङ्कलित दूध (लिटर) | C24: Number | D24: =Questions!D78 | E24: =Questions!E78 -> 310000
A25: 24 | B25: Milk Loss (Liters),बिग्रिएको / नोक्सानी भएको दूध (लिटर) | C25: Number | D25: =Questions!D79+Questions!D80 -> 0 | E25: =Questions!E79+Questions!E80 -> 20000
A26: 25 | B26: Produced Milk (Liters) [Model B],उत्पादन गरिएको दूध (लिटर) | C26: Number | D26: =Questions!D78-Questions!D79 -> 0 | E26: =Questions!E78-Questions!E79 -> 300000
A27: 26 | B27: Sold Products Value (NPR) [Model B],बिक्री भएका उत्पादनको मूल्य (रु) | C27: Number | D27: =Questions!D16 | E27: =Questions!E16 -> 30000000
A28: 27 | B28: Lean Month Expenses,न्यूनतम महिना खर्च (रु) | C28: Number | D28: =Questions!D46 | E28: =Questions!E46 -> 433333.33
A29: 28 | B29: Total Member Loans (NPR),सदस्यहरूलाई दिएको कुल ऋण (रु) | C29: Number | D29: =Questions!D93 | E29: =Questions!E93 -> 15000000
A30: 29 | B30: NPA Member Loans (NPR),खराब / एनपीए सदस्य ऋण (रु) | C30: Number | D30: =Questions!D94 | E30: =Questions!E94 -> 2500000
A31: 30 | B31: Bank Sales (NPR),बैंकमार्फत भएको बिक्री (रु) | C31: Number | D31: =Questions!D19 | E31: =Questions!E19 -> 15000000
A32: 31 | B32: Total Sales (NPR),कुल बिक्री (रु) | C32: Number | D32: =Questions!D18 | E32: =Questions!E18 -> 30500000
A33: 32 | B33: Key Mgmt Experience (Avg Years),प्रमुख व्यवस्थापनको औसत अनुभव (वर्ष) | C33: Number | D33: =Questions!D101 | E33: =Questions!E101 -> 8
A34: 33 | B34: Internal Controls Score,आन्तरिक नियन्त्रण स्कोर | C34: Dropdown | D34: =Questions!D102 | E34: =Questions!E102 -> Robust
A35: 34 | B35: Audit Findings (#),अडिटमा देखिएका कैफियत संख्या | C35: Dropdown | D35: =Questions!D103 | E35: =Questions!E103 -> Few
A36: 35 | B36: Lending Policy Compliance,ऋण नीतिको पालना | C36: Dropdown | D36: =Questions!D104 | E36: =Questions!E104 -> Yes
A37: 36 | B37: Collection Average,दूध सङ्कलनका औसत दिनहरू | C37: Dropdown | D37: =IF(Questions!D92>325,"High",IF(Questions!D92>300,"Medium","Low")) -> Low | E37: =IF(Questions!E92>325,"High",IF(Questions!E92>300,"Medium","Low")) -> High
A38: 37 | B38: Fleet Availability,सङ्कलन सवारी साधन उपलब्धता | C38: Dropdown | D38: =Questions!D105 | E38: =Questions!E105 -> Yes
A39: 38 | B39: Storage / Cold Chain Availability,भण्डारण / चिसो श्रृंखला उपलब्धता | C39: Dropdown | D39: =Questions!D106 | E39: =Questions!E106 -> Yes
A40: 39 | B40: Are there any standards for milk collection, handling, and storage? If yes, are the written documents for them available?के दूध सङ्कलन, व्यवस्थापन, र भण्डारणका लागि मापदण्डहरू छन्? यदि छन् भने, के तिनीहरूको लिखित दस्तावेज उपलब्ध छ? | C40: Dropdown | D40: =Questions!D107 | E40: =Questions!E107 -> Standards and documents exist. मापदण्ड र दस्तावेज छन्
...

Sheet Calculations
A1: S.N | B1: Sub-Indicators | C1: Score | D1: Placeholder
A2: 1 | B2: DSCR | C2: =Data!D8/(Data!D9+Data!D10) -> #DIV/0! | D2: =Data!E8/(Data!E9+Data!E10) -> 1.0334928
A3: 2 | B3: Seasonality Coverage | C3: =Data!D41/Data!D28 -> #DIV/0! | D3: =Data!E41/Data!E28 -> 10.384615
A4: 3 | B4: Inventory Days | C4: =(Data!D19/Data!D20)*365 -> #DIV/0! | D4: =(Data!E19/Data!E20)*365 -> 542.56757
A5: 4 | B5: Receivable Days | C5: =(Data!D21/Data!D7)*365 -> #DIV/0! | D5: =(Data!E21/Data!E7)*365 -> 41.885246
A6: 5 | B6: Milk Stability % | C6: =(Data!D23/Data!D22)*100 -> #DIV/0! | D6: =(Data!E23/Data!E22)*100 -> 82.758621
A7: 6 | B7: Days Stability % | C7: =(Data!D52/365)*100 -> 0 | D7: =(Data!E52/365)*100 -> 89.315068
A8: 7 | B8: Milk Loss % | C8: =(Data!D25/Data!D24)*100 -> #DIV/0! | D8: =(Data!E25/Data!E24)*100 -> 6.4516129
A9: 8 | B9: Yield Loss % | C9: =(Data!D25/Data!D26)*100 -> #DIV/0! | D9: =(Data!E25/Data!E26)*100 -> 6.6666667
A10: 9 | B10: Farmer Concentration % | C10: =(Data!D46/Data!D47)*100 -> #DIV/0! | D10: =(Data!E46/Data!E47)*100 -> 40.322581
A11: 10 | B11: Collection Stability % | C11: =(Data!D47/Data!D29) -> #DIV/0! | D11: =(Data!E47/Data!E29) -> 0.020666667
A12: 11 | B12: Payment Fairness % | C12: =1-(Data!D44/30) -> 1 | D12: =1-(Data!E44/30) -> 0.5
A13: 12 | B13: Logistics Reliability | C13: =Data!D38 | D13: =Data!E38 -> Yes
A14: 13 | B14: Net Worth | C14: =Data!D11-Data!D12 -> 0 | D14: =Data!E11-Data!E12 -> 25000000
A15: 14 | B15: Debt/Equity | C15: =Data!D15/Data!D16 -> #DIV/0! | D15: =Data!E15/Data!E16 -> 0.54545455
A16: 15 | B16: Current Ratio | C16: =Data!D13/Data!D14 -> #DIV/0! | D16: =Data!E13/Data!E14 -> 3.3333333
A17: 16 | B17: Grant % | C17: =(Data!D17/Data!D7) -> #DIV/0! | D17: =(Data!E17/Data!E7) -> 0.016393443
A18: 17 | B18: Cash / Bank Balance Trend | C18: =IF(Data!D41>Data!D42,"UP",IF(Data!D41<Data!D42,"DOWN","STABLE")) -> STABLE | D18: =IF(Data!E41>Data!E42,"UP",IF(Data!E41<Data!E42,"DOWN","STABLE")) -> UP
A19: 18 | B19: Member GNPA % | C19: =(Data!D30/Data!D29) -> #DIV/0! | D19: =(Data!E30/Data!E29) -> 0.16666667
A20: 19 | B20: Max DPD | C20: =Data!D44 | D20: =Data!E44 -> 15
A21: 20 | B21: Restructuring | C21: =Data!D45 | D21: =Data!E45 -> Few Times
A22: 21 | B22: Mgmt Experience | C22: =Data!D33 | D22: =Data!E33 -> 8
A23: 22 | B23: Internal Controls | C23: =Data!D34 | D23: =Data!E34 -> Robust
A24: 23 | B24: Audit Findings | C24: =Data!D35 | D24: =Data!E35 -> Few
A25: 24 | B25: Lending Policy Compliance | C25: =Data!D36 | D25: =Data!E36 -> Yes
A26: 25 | B26: Quality SOP | C26: =Data!D40 | D26: =Data!E40 -> Standards and documents exist. मापदण्ड र दस्तावेज छन्
A27: 26 | B27: % Sales via Bank | C27: =(Data!D31/Data!D32)*100 -> #DIV/0! | D27: =(Data!E31/Data!E32)*100 -> 49.180328
A28: 27 | B28: Insurance Coverage | C28: =Data!D54 | D28: =Data!E54 -> Yes
A29: 28 | B29: Digital MIS / POS / QR Adoption | C29: =Data!D55 | D29: =Data!E55 -> Yes
A30: 29 | B30: Regulatory Compliance | C30: =Data!D56 | D30: =Data!E56 -> Partial
A31: 30 | B31: Climatic / Input Risk | C31: =Data!D57 | D31: =Data!E57 -> Low
A32: 31 | B32: Credit History | C32: =Data!D58 | D32: =Data!E58 -> Pass
A33: 32 | B33: Max Delays | C33: =Data!D59 | D33: =Data!E59 -> 5
A34: 33 | B34: Top 5 concentration(%) | C34: =Data!D61/Data!D32*100 -> #DIV/0! | D34: =Data!E61/Data!E32*100 -> 26.229508
A35: 34 | B35: Largest buyer concentration (%) | C35: =(Data!D62/Data!D32)*100 -> #DIV/0! | D35: =(Data!E62/Data!E32)*100 -> 6.557377
A36: 35 | B36: Stable buyer share (%) | C36: =(Data!D63+Data!D64)/Data!D60 -> #DIV/0! | D36: =(Data!E63+Data!E64)/Data!E60 -> 0.5
A37: 36 | B37: Contract score | C37: =Data!D67 -> #DIV/0! | D37: =Data!E67 -> 0.66666667
A38: 37 | B38: Payment score | C38: =1-(Data!D66/90) -> 1 | D38: =1-(Data!E66/90) -> 0.61111111
A39: 38 | B39: Committee Meeting Frequency | C39: =Data!D68 | D39: =Data!E68 -> Weekly
A40: 39 | B40: Member Info Transparency | C40: =Data!D69 | D40: =Data!E69 -> Always
...

Sheet Model
A1: SN | B1: Parameter | C1: Parameter Weight (Points) | D1: Weight for sub-parameters | E1: Sub-Parameter | F1: Sub Weight (Points) | G1: Placeholder | H1: Data(value)
A2: 1 | B2: Cash Flow & Loan Repayment | C2: 180 | D2: 60 | E2: DSCR | F2: =IF(Calculations!C2>=1.5,60, IF(Calculations!C2>=1.25,48, IF(Calculations!C2>=1,36, IF(Calculations!C2>=0.8,20,0) ) ) ) -> #DIV/0! | G2: =IF(Calculations!D2>=1.5,60, IF(Calculations!D2>=1.25,48, IF(Calculations!D2>=1,36, IF(Calculations!D2>=0.8,20,0) ) ) ) -> 36 | H2: 36
B3: Cash Flow & Loan Repayment | D3: 50 | E3: Seasonality Coverage | F3: =IF(Calculations!C3>=20,50, IF(Calculations!C3>=15,40, IF(Calculations!C3>=10,30, IF(Calculations!C3>=5,20,0) ) ) ) -> #DIV/0! | G3: =IF(Calculations!D3>=20,50, IF(Calculations!D3>=15,40, IF(Calculations!D3>=10,30, IF(Calculations!D3>=5,20,0) ) ) ) -> 30 | H3: 30
B4: Cash Flow & Loan Repayment | D4: 30 | E4: Inventory Days | F4: =IF(Calculations!C4>=60,30, IF(Calculations!C4>=90,24, IF(Calculations!C4>=120,18, IF(Calculations!C4>=180,10,0) ) ) ) -> #DIV/0! | G4: =IF(Calculations!D4>=60,30, IF(Calculations!D4>=90,24, IF(Calculations!D4>=120,18, IF(Calculations!D4>=180,10,0) ) ) ) -> 30 | H4: 30
B5: Cash Flow & Loan Repayment | D5: 40 | E5: Receivable Days | F5: =IF(Calculations!C5>=30,40, IF(Calculations!C5>=45,32, IF(Calculations!C5>=60,24, IF(Calculations!C5>=90,12,0) ) ) ) -> #DIV/0! | G5: =IF(Calculations!D5>=30,40, IF(Calculations!D5>=45,32, IF(Calculations!D5>=60,24, IF(Calculations!D5>=90,12,0) ) ) ) -> 40 | H5: 40
A6: 2 | B6: Milk Supply & Operational Stability | C6: 150 | D6: 30 | E6: Milk Stability % | F6: =IF(Calculations!C6>=90,30, IF(Calculations!C6>=80,24, IF(Calculations!C6>=70,18, IF(Calculations!C6>=60,10,0) ) ) ) -> #DIV/0! | G6: =IF(Calculations!D6>=90,30, IF(Calculations!D6>=80,24, IF(Calculations!D6>=70,18, IF(Calculations!D6>=60,10,0) ) ) ) -> 24 | H6: 18
B7: Milk Supply & Operational Stability | D7: 20 | E7: Days Stability % | F7: =IF(Calculations!C7>=95,20, IF(Calculations!C7>=85,15, IF(Calculations!C7>=75,10, IF(Calculations!C7>=65,5,0) ) ) ) -> 0 | G7: =IF(Calculations!D7>=95,20, IF(Calculations!D7>=85,15, IF(Calculations!D7>=75,10, IF(Calculations!D7>=65,5,0) ) ) ) -> 15 | H7: 15
B8: Milk Supply & Operational Stability | D8: 20 | E8: Milk Loss % | F8: =IF(Calculations!C8>=2,20, IF(Calculations!C8>=5,16, IF(Calculations!C8>=8,10, IF(Calculations!C8>=12,5,0) ) ) ) -> #DIV/0! | G8: =IF(Calculations!D8>=2,20, IF(Calculations!D8>=5,16, IF(Calculations!D8>=8,10, IF(Calculations!D8>=12,5,0) ) ) ) -> 20 | H8: 20
B9: Milk Supply & Operational Stability | D9: 20 | E9: Yield Loss % | F9: =IF(Calculations!C9>=2,20, IF(Calculations!C9>=5,15, IF(Calculations!C9>=8,10, IF(Calculations!C9>=12,5,0) ) ) ) -> #DIV/0! | G9: =IF(Calculations!D9>=2,20, IF(Calculations!D9>=5,15, IF(Calculations!D9>=8,10, IF(Calculations!D9>=12,5,0) ) ) ) -> 20 | H9: 20
B10: Milk Supply & Operational Stability | D10: 15 | E10: Farmer Concentration % | F10: =IF(Calculations!C10>=20,15, IF(Calculations!C10>=35,12, IF(Calculations!C10>=50,8, IF(Calculations!C10>=70,4,0) ) ) ) -> #DIV/0! | G10: =IF(Calculations!D10>=20,15, IF(Calculations!D10>=35,12, IF(Calculations!D10>=50,8, IF(Calculations!D10>=70,4,0) ) ) ) -> 15 | H10: 15
B11: Milk Supply & Operational Stability | D11: 15 | E11: Collection Stability % | F11: =IF(Calculations!C11>=15%,15, IF(Calculations!C11>=10%,12, IF(Calculations!C11>=5%,8, IF(Calculations!C11>=1%,4,0) ) ) ) -> #DIV/0! | G11: =IF(Calculations!D11>=15%,15, IF(Calculations!D11>=10%,12, IF(Calculations!D11>=5%,8, IF(Calculations!D11>=1%,4,0) ) ) ) -> 4 | H11: 4
B12: Milk Supply & Operational Stability | D12: 15 | E12: Payment Fairness % | F12: =IF(Calculations!C12>=85%,15, IF(Calculations!C12>=70%,12, IF(Calculations!C12>=55%,8, IF(Calculations!C12>=40%,4,0) ) ) ) -> 15 | G12: =IF(Calculations!D12>=85%,15, IF(Calculations!D12>=70%,12, IF(Calculations!D12>=55%,8, IF(Calculations!D12>=40%,4,0) ) ) ) -> 4 | H12: 4
B13: Milk Supply & Operational Stability | D13: 15 | E13: Logistics Reliability | F13: =IF( Calculations!C13="Yes",15,0) -> 0 | G13: =IF( Calculations!D13="Yes",15,0) -> 15 | H13: 15
A14: 3 | B14: Financial Strength & Liquidity | C14: 180 | D14: 40 | E14: Net Worth | F14: =IF(Calculations!C14>(Data!D5+Data!D6),40,IF(Calculations!C14=(Data!D5+Data!D6)*20,30,15)) -> 30 | G14: =IF(Calculations!D14>(Data!E5+Data!E6),40,IF(Calculations!D14=(Data!E5+Data!E6)*20,30,15)) -> 40 | H14: 40
B15: Financial Strength & Liquidity | D15: 40 | E15: Debt / Equity | F15: =IF(Calculations!C15<=0.5,40, IF(Calculations!C15<=1,32, IF(Calculations!C15<=2,20, IF(Calculations!C15<=3,10,0)))) -> #DIV/0! | G15: =IF(Calculations!D15<=0.5,40, IF(Calculations!D15<=1,32, IF(Calculations!D15<=2,20, IF(Calculations!D15<=3,10,0)))) -> 32 | H15: 32
B16: Financial Strength & Liquidity | D16: 40 | E16: Current Ratio | F16: =IF(Calculations!C16>=2,40, IF(Calculations!C16>=1.5,30, IF(Calculations!C16>=1,20, IF(Calculations!C16>=0.5,10,0)))) -> #DIV/0! | G16: =IF(Calculations!D16>=2,40, IF(Calculations!D16>=1.5,30, IF(Calculations!D16>=1,20, IF(Calculations!D16>=0.5,10,0)))) -> 40 | H16: 40
B17: Financial Strength & Liquidity | D17: 30 | E17: Grant % of Revenue | F17: =IF(Calculations!C17<=0.02,30, IF(Calculations!C17<=0.05,15, IF(Calculations!C17<=0.1,10,0))) -> #DIV/0! | G17: =IF(Calculations!D17<=0.02,30, IF(Calculations!D17<=0.05,15, IF(Calculations!D17<=0.1,10,0))) -> 30 | H17: 30
B18: Financial Strength & Liquidity | D18: 30 | E18: Cash / Bank Balance Trend | F18: =IF(Calculations!C18="UP",30, IF(Calculations!C18="STABLE",15,0)) -> 15 | G18: =IF(Calculations!D18="UP",30, IF(Calculations!D18="STABLE",15,0)) -> 30 | H18: 30
A19: 4 | B19: Financial Transparency & Cash Discipline | C19: 50 | D19: 25 | E19: % Sales via Bank | F19: =IF(Calculations!C27>80%,25, IF(Calculations!C27>50%,15,0)) -> #DIV/0! | G19: =IF(Calculations!D27>80%,25, IF(Calculations!D27>50%,15,0)) -> 25 | H19: 25
B20: Financial Transparency & Cash Discipline | D20: 25 | E20: Digital MIS / POS / QR Adoption | F20: =IF(Calculations!C29="Yes",25,0) -> 0 | G20: =IF(Calculations!D29="Yes",25,0) -> 25 | H20: 25
A21: 5 | B21: Loan Recovery & Member Credit Risk | C21: 100 | D21: 45 | E21: Member GNPA % | F21: =IF(Calculations!C19<=5%,45, IF(Calculations!C19<=10%,35, IF(Calculations!C19<=15%,25, IF(Calculations!C19<=20%,15,0)))) -> #DIV/0! | G21: =IF(Calculations!D19<=5%,45, IF(Calculations!D19<=10%,35, IF(Calculations!D19<=15%,25, IF(Calculations!D19<=20%,15,0)))) -> 15 | H21: 15
B22: Loan Recovery & Member Credit Risk | D22: 35 | E22: Max DPD | F22: =IF(Calculations!C20<=5,35, IF(Calculations!C20<=10,25, IF(Calculations!C20<=15,15,0))) -> 35 | G22: =IF(Calculations!D20<=5,35, IF(Calculations!D20<=10,25, IF(Calculations!D20<=15,15,0))) -> 15 | H22: 15
B23: Loan Recovery & Member Credit Risk | D23: 20 | E23: Restructuring | F23: =IF(Calculations!C21="Never",20, IF(Calculations!C21="Few Times",15,0)) -> 0 | G23: =IF(Calculations!D21="Never",20, IF(Calculations!D21="Few Times",15,0)) -> 15 | H23: 15
A24: 6 | B24: Management & Governance Quality | C24: 100 | D24: 25 | E24: Management Experience | F24: =IF(Calculations!C22>=10,25, IF(Calculations!C22>=7,15, IF(Calculations!C22>=5,10,0))) -> 0 | G24: =IF(Calculations!D22>=10,25, IF(Calculations!D22>=7,15, IF(Calculations!D22>=5,10,0))) -> 15 | H24: 15
B25: Management & Governance Quality | D25: 25 | E25: Internal Controls | F25: =IF(Calculations!C23="Robust",25, IF(Calculations!C23="Moderate",10,0)) -> 0 | G25: =IF(Calculations!D23="Robust",25, IF(Calculations!D23="Moderate",10,0)) -> 25 | H25: 25
B26: Management & Governance Quality | D26: 25 | E26: Audit Findings | F26: =IF(Calculations!C24="None",25, IF(Calculations!C24="Few",15,0)) -> 0 | G26: =IF(Calculations!D24="None",25, IF(Calculations!D24="Few",15,0)) -> 15 | H26: 15
B27: Management & Governance Quality | D27: 25 | E27: Lending Policy Compliance | F27: =IF(Calculations!C25="Yes",25,0) -> 0 | G27: =IF(Calculations!D25="Yes",25,0) -> 25 | H27: 25
A28: 7 | B28: Operational Quality | C28: 40 | D28: 40 | E28: Quality SOP Compliance | F28: =IF(Calculations!C26>=9,40, IF(Calculations!C26>=7,30, IF(Calculations!C26>=5,20, IF(Calculations!C26>=3,10,0)))) -> 0 | G28: =IF(Calculations!D26>=9,40, IF(Calculations!D26>=7,30, IF(Calculations!D26>=5,20, IF(Calculations!D26>=3,10,0)))) -> 40 | H28: 40
A29: 8 | B29: External & Regulatory Risk | C29: 40 | D29: 10 | E29: Insurance Coverage | F29: =IF(Calculations!C28="Yes",10,0) -> 0 | G29: =IF(Calculations!D28="Yes",10,0) -> 10 | H29: 10
B30: External & Regulatory Risk | D30: 15 | E30: Regulatory Compliance | F30: =IF(Calculations!C30="Full", 10, IF(Calculations!C30="Partial", 5, 0)) -> 0 | G30: =IF(Calculations!D30="Full", 10, IF(Calculations!D30="Partial", 5, 0)) -> 5 | H30: 5
B31: External & Regulatory Risk | D31: 15 | E31: Climatic Risk | F31: =IF(Calculations!C31="Low",15, IF(Calculations!C31="Medium",10,0)) -> 0 | G31: =IF(Calculations!D31="Low",15, IF(Calculations!D31="Medium",10,0)) -> 15 | H31: 0
A32: 9 | B32: Credit History / Banking Behaviour | C32: 40 | D32: 20 | E32: Credit History | F32: =IF(Calculations!C32="Pass",20,IF(Calculations!C32="Watchlist",15,IF(Calculations!C32="Substandard",10,0))) -> 0 | G32: =IF(Calculations!D32="Pass",20,IF(Calculations!D32="Watchlist",15,IF(Calculations!D32="Substandard",10,0))) -> 20 | H32: 20
B33: Credit History / Banking Behaviour | D33: 20 | E33: Max Delays | F33: =IF(Calculations!C33<=5,20, IF(Calculations!C33<=10,15, IF(Calculations!C33<=15,10,0))) -> 20 | G33: =IF(Calculations!D33<=5,20, IF(Calculations!D33<=10,15, IF(Calculations!D33<=15,10,0))) -> 20 | H33: 20
A34: 10 | B34: Buyer Concentration & Market Risk | C34: 80 | D34: 25 | E34: Top 5 Buyer Concentration % | F34: =IF(Calculations!C34<=20,25, IF(Calculations!C34<=30,20, IF(Calculations!C34<=40,15, IF(Calculations!C34<=50,10,5)))) -> #DIV/0! | G34: =IF(Calculations!D34<=20,25, IF(Calculations!D34<=30,20, IF(Calculations!D34<=40,15, IF(Calculations!D34<=50,10,5)))) -> 20 | H34: 20
B35: Buyer Concentration & Market Risk | D35: 25 | E35: Largest Buyer Concentration % | F35: =IF(Calculations!C35<=20,25, IF(Calculations!C35<=30,20, IF(Calculations!C35<=40,15, IF(Calculations!C35<=50,10,5)))) -> #DIV/0! | G35: =IF(Calculations!D35<=20,25, IF(Calculations!D35<=30,20, IF(Calculations!D35<=40,15, IF(Calculations!D35<=50,10,5)))) -> 25 | H35: 25
B36: Buyer Concentration & Market Risk | D36: 10 | E36: Stable Buyer Share % | F36: =IF(Calculations!C36>=60%,10, IF(Calculations!C36>=40%,5,0)) -> #DIV/0! | G36: =IF(Calculations!D36>=60%,10, IF(Calculations!D36>=40%,5,0)) -> 5 | H36: 5
B37: Buyer Concentration & Market Risk | D37: 10 | E37: Contract Coverage % | F37: =IF(Calculations!C37>=80%,10, IF(Calculations!C37>=50%,5,0)) -> #DIV/0! | G37: =IF(Calculations!D37>=80%,10, IF(Calculations!D37>=50%,5,0)) -> 5 | H37: 5
B38: Buyer Concentration & Market Risk | D38: 10 | E38: Payment Score | F38: =IF(Calculations!C41>=90%,10, IF(Calculations!C41>=70%,5,0)) -> 0 | G38: =IF(Calculations!D41>=90%,10, IF(Calculations!D41>=70%,5,0)) -> 10 | H38: 10
A39: 11 | B39: Behavioural & Due Diligence Risk | C39: 40 | D39: 5 | E39: Committee Meeting Frequency | F39: =IF(Calculations!C39="Weekly",5, IF(Calculations!C39="Monthly",2.5, IF(Calculations!C39="Quarterly",1.5, IF(Calculations!C39="Yearly",1,0)))) -> 0 | G39: =IF(Calculations!D39="Weekly",5, IF(Calculations!D39="Monthly",2.5, IF(Calculations!D39="Quarterly",1.5, IF(Calculations!D39="Yearly",1,0)))) -> 5 | H39: 5
B40: Behavioural & Due Diligence Risk | D40: 5 | E40: Member Info Transparency | F40: =IF(Calculations!C40="Always",5, IF(Calculations!C40="Mostly",2.5, IF(Calculations!C40="Sometimes",1.5, IF(Calculations!C40="Decided among few",1,0)))) -> 0 | G40: =IF(Calculations!D40="Always",5, IF(Calculations!D40="Mostly",2.5, IF(Calculations!D40="Sometimes",1.5, IF(Calculations!D40="Decided among few",1,0)))) -> 5 | H40: 5
...

Sheet DropdownOptions
A1: bifurcation | B1: option
A2: model_type | B2: Milk Collection Only / केवल दूध सङ्कलन
A3: model_type | B3: Processing / प्रशोधन
A4: is_existing | B4: New / नयाँ
A5: is_existing | B5: Existing / पहिलेबाट रहेको
A6: repayment_frequency | B6: Monthly / मासिक
A7: repayment_frequency | B7: Quarterly / त्रैमासिक
A8: repayment_frequency | B8: Anually / वार्षिक
A9: restructured_loans_past3yrs | B9: Never / कहिल्यै होइन
A10: restructured_loans_past3yrs | B10: Few Times / केही पटक
A11: restructured_loans_past3yrs | B11: Frequent / बारम्बार
A12: credit_history_flag | B12: Timley / समयमा
... A75: Emergency Preparedness | B75: Proper Plan / उचित योजना

Sheet Submissions
A1: Submission Timestamp | B1: Server Timestamp | C1: Total Score | D1: Risk Tier | E1: Coop Name | F1: Answers JSON | G1: Submission ID | H1: Approver Status | I1: Approver Notes | J1: Approver Decided At
A2: 2026-03-18T03:50:18.310Z | B2: 46099.4 | C2: 299 | D2: D Risk | E2: Failing Test Cooperative (Test) | F2: {"model_type":"","loan_type":"","coop_name":"Failing Test Cooperative (Test)","years_operation":1,"office_location":"Remote District","total_loan":"9000000","existing_loan":3000000,"proposed_loan":6000000,"interest_rate":16,"loan_tenure":36,"installment_freq":"Annual","primary_land_value":2000000,"total_sales":"8100000","total_revenue":"13100000","milk_sales":8000000,"other_product_sales":0,"other_income":100000,"grant_income":5000000,"bank_sales":2000000,"top5_buyer_pct":"80.25","largest_buyer_pct":"49.38","total_buyers":50,"top5_buyers_sales":6500000,"largest_buyer_sales":4000000,"gov_buyer_sales":500000,"no_govt_buyers":1,"large_private_buyer_sales":3000000,"no_private_sector_buyer":2,"small_buyer_sales":2000000,"no_small_buyer_sales":20,"avg_collection_days":90,"contract_coverage":0,"total_opex":"9110000","raw_milk_cost":7000000,"processing_cost":0,"packaging_cost":0,"transport_cost":300000,"other_processing_cost":0,"salary_expense":900000,"admin_expense":300000,"electricity_expense":150000,"fuel_expense":120000,"repair_expense":80000,"rent_expense":60000,"other_opex":200000,"lowest_monthly_expense":700000,"annual_depreciation":200000,"amortization_amount":0,"total_cash":"400000","total_current_assets":"3100000","total_fixed_assets":"3230000","total_assets":"6330000","cash_hand":50000,"bank_balance":350000,"accounts_receivable":2500000,"inventory_value":150000,"prepaid_expenses":0,"other_current_assets":50000,"land_value":1800000,"building_value":600000,"machinery_value":400000,"vehicle_value":300000,"furniture_value":80000,"other_fixed_assets":50000,"total_current_liabilities":"6300000","total_long_term_liabilities":"5800000","total_liabilities":"12100000","accounts_payable":1500000,"short_term_loan":3000000,"accrued_expenses":600000,"current_ltd":1200000,"long_term_loan":4800000,"other_ltl":1000000,"total_net_worth":"400000","paid_up_capital":500000,"retained_earnings":-200000,"reserve_fund":100000,"total_milk_sold":"630000","avg_milk_per_farmer":"7777.78","total_milk_collected":700000,"milk_loss":70000,"processing_loss":0,"avg_monthly_milk":58000,"lowest_monthly_milk":20000,"highest_monthly_milk":90000,"avg_inventory_value":100000,"credit_period_given_days":45,"top5_farmers_milk":420000,"highest_farmer_qty":30000,"lowest_farmer_qty":200,"total_farmers":90,"collection_days":260,"total_member_loans":2000000,"npa_member_loans":600000,"overdue_member_loans":800000,"restructured_loans_3yr":"Frequently","max_dpd_members":120,"credit_history_flag":"Frequent delays","cash_last_year":400000,"cash_prev_year":700000,"audit_observations":10,"mgmt_experience":1,"internal_control_score":"20","loan_policy_compliance":"No","vehicle_avail_pct":"No","storage_cold_facility":"No","quality_sop_score":"15","insurance_available":"No","digital_mis_pos":"No","regulatory_compliance":"No","climatic_risk_score":"8","credit_history_bfi":"Substandard","max_dpd_bfi":45,"meeting_frequency":"Rarely","member_info_transparency":"Decided among few","fund_usage":"Other things","kyc_aml":"Hard","income_expense_checked":"Never","right_to_information":"Only after implementation","community_support_level":"Minimal","emergency_response":"No Plan","customer_type":"new"} | G2: SUB-DA4645BB-B2D | H2: pending
A3: 2026-03-18T03:54:07.098Z | B3: 46099.402 | C3: 900 | D3: A Risk | E3: Himalayan Dairy Cooperative (Test) | F3: {"model_type":"","loan_type":"","coop_name":"Himalayan Dairy Cooperative (Test)","years_operation":15,"office_location":"Lalitpur, Bagmati","total_loan":"3000000","existing_loan":0,"proposed_loan":3000000,"interest_rate":9,"loan_tenure":60,"installment_freq":"Monthly","primary_land_value":9000000,"total_sales":"45500000","total_revenue":"45700000","milk_sales":42000000,"other_product_sales":3000000,"other_income":500000,"grant_income":200000,"bank_sales":38000000,"top5_buyer_pct":"21.98","largest_buyer_pct":"5.49","total_buyers":500,"top5_buyers_sales":10000000,"largest_buyer_sales":2500000,"gov_buyer_sales":8000000,"no_govt_buyers":3,"large_private_buyer_sales":20000000,"no_private_sector_buyer":5,"small_buyer_sales":500000,"no_small_buyer_sales":10,"avg_collection_days":20,"contract_coverage":8,"total_opex":"32050000","raw_milk_cost":28000000,"processing_cost":0,"packaging_cost":0,"transport_cost":600000,"other_processing_cost":0,"salary_expense":2000000,"admin_expense":500000,"electricity_expense":300000,"fuel_expense":200000,"repair_expense":150000,"rent_expense":100000,"other_opex":200000,"lowest_monthly_expense":250000,"annual_depreciation":800000,"amortization_amount":100000,"total_cash":"5500000","total_current_assets":"7200000","total_fixed_assets":"15500000","total_assets":"22700000","cash_hand":500000,"bank_balance":5000000,"accounts_receivable":800000,"inventory_value":600000,"prepaid_expenses":100000,"other_current_assets":200000,"land_value":8000000,"building_value":3000000,"machinery_value":2500000,"vehicle_value":1500000,"furniture_value":300000,"other_fixed_assets":200000,"total_current_liabilities":"1000000","total_long_term_liabilities":"2400000","total_liabilities":"3400000","accounts_payable":300000,"short_term_loan":0,"accrued_expenses":100000,"current_ltd":600000,"long_term_loan":2400000,"other_ltl":0,"total_net_worth":"11000000","paid_up_capital":5000000,"retained_earnings":4000000,"reserve_fund":2000000,"total_milk_sold":"4158000","avg_milk_per_farmer":"6000","total_milk_collected":4200000,"milk_loss":42000,"processing_loss":0,"avg_monthly_milk":350000,"lowest_monthly_milk":310000,"highest_monthly_milk":420000,"avg_inventory_value":400000,"credit_period_given_days":7,"top5_farmers_milk":500000,"highest_farmer_qty":90000,"lowest_farmer_qty":1000,"total_farmers":700,"collection_days":355,"total_member_loans":8000000,"npa_member_loans":80000,"overdue_member_loans":120000,"restructured_loans_3yr":"None","max_dpd_members":10,"credit_history_flag":"Timely","cash_last_year":5500000,"cash_prev_year":4200000,"audit_observations":0,"mgmt_experience":12,"internal_control_score":"85","loan_policy_compliance":"Yes","vehicle_avail_pct":"Yes","storage_cold_facility":"Yes","quality_sop_score":"85","insurance_available":"Yes","digital_mis_pos":"Yes","regulatory_compliance":"Yes","climatic_risk_score":"2","credit_history_bfi":"Pass","max_dpd_bfi":0,"meeting_frequency":"Weekly","member_info_transparency":"Always","fund_usage":"Buying Milk","kyc_aml":"Easily Found","income_expense_checked":"Regularly","right_to_information":"Always Beforehand","community_support_level":"Significant","emergency_response":"Proper Plan","customer_type":"existing"} | G3: SUB-D5192A51-F19 | H3: pending
A4: 2026-03-18T04:20:13.799Z | B4: 46099.42 | C4: 900 | D4: A Risk | E4: Himalayan Dairy Cooperative (Test) | F4: {"model_type":"","loan_type":"","coop_name":"Himalayan Dairy Cooperative (Test)","years_operation":15,"office_location":"Lalitpur, Bagmati","total_loan":"3000000","existing_loan":0,"proposed_loan":3000000,"interest_rate":9,"loan_tenure":60,"installment_freq":"Monthly","primary_land_value":9000000,"total_sales":"45500000","total_revenue":"45700000","milk_sales":42000000,"other_product_sales":3000000,"other_income":500000,"grant_income":200000,"bank_sales":38000000,"top5_buyer_pct":"21.98","largest_buyer_pct":"5.49","total_buyers":500,"top5_buyers_sales":10000000,"largest_buyer_sales":2500000,"gov_buyer_sales":8000000,"no_govt_buyers":3,"large_private_buyer_sales":20000000,"no_private_sector_buyer":5,"small_buyer_sales":500000,"no_small_buyer_sales":10,"avg_collection_days":20,"contract_coverage":8,"total_opex":"32050000","raw_milk_cost":28000000,"processing_cost":0,"packaging_cost":0,"transport_cost":600000,"other_processing_cost":0,"salary_expense":2000000,"admin_expense":500000,"electricity_expense":300000,"fuel_expense":200000,"repair_expense":150000,"rent_expense":100000,"other_opex":200000,"lowest_monthly_expense":250000,"annual_depreciation":800000,"amortization_amount":100000,"total_cash":"5500000","total_current_assets":"7200000","total_fixed_assets":"15500000","total_assets":"22700000","cash_hand":500000,"bank_balance":5000000,"accounts_receivable":800000,"inventory_value":600000,"prepaid_expenses":100000,"other_current_assets":200000,"land_value":8000000,"building_value":3000000,"machinery_value":2500000,"vehicle_value":1500000,"furniture_value":300000,"other_fixed_assets":200000,"total_current_liabilities":"1000000","total_long_term_liabilities":"2400000","total_liabilities":"3400000","accounts_payable":300000,"short_term_loan":0,"accrued_expenses":100000,"current_ltd":600000,"long_term_loan":2400000,"other_ltl":0,"total_net_worth":"11000000","paid_up_capital":5000000,"retained_earnings":4000000,"reserve_fund":2000000,"total_milk_sold":"4158000","avg_milk_per_farmer":"6000","total_milk_collected":4200000,"milk_loss":42000,"processing_loss":0,"avg_monthly_milk":350000,"lowest_monthly_milk":310000,"highest_monthly_milk":420000,"avg_inventory_value":400000,"credit_period_given_days":7,"top5_farmers_milk":500000,"highest_farmer_qty":90000,"lowest_farmer_qty":1000,"total_farmers":700,"collection_days":355,"total_member_loans":8000000,"npa_member_loans":80000,"overdue_member_loans":120000,"restructured_loans_3yr":"None","max_dpd_members":10,"credit_history_flag":"Timely","cash_last_year":5500000,"cash_prev_year":4200000,"audit_observations":0,"mgmt_experience":12,"internal_control_score":"85","loan_policy_compliance":"Yes","vehicle_avail_pct":"Yes","storage_cold_facility":"Yes","quality_sop_score":"85","insurance_available":"Yes","digital_mis_pos":"Yes","regulatory_compliance":"Yes","climatic_risk_score":"2","credit_history_bfi":"Pass","max_dpd_bfi":0,"meeting_frequency":"Weekly","member_info_transparency":"Always","fund_usage":"Buying Milk","kyc_aml":"Easily Found","income_expense_checked":"Regularly","right_to_information":"Always Beforehand","community_support_level":"Significant","emergency_response":"Proper Plan","customer_type":"new"} | G4: SUB-5C8A7791-7B4 | H4: pending
A5: 2026-03-18T04:35:25.015Z | B5: 46099.431 | C5: 519 | D5: C Risk | E5: Koshi Valley Cooperative (Test) | F5: {"model_type":"","loan_type":"","coop_name":"Koshi Valley Cooperative (Test)","years_operation":4,"office_location":"Morang, Koshi","total_loan":"6500000","existing_loan":1500000,"proposed_loan":5000000,"interest_rate":12,"loan_tenure":48,"installment_freq":"Quarterly","primary_land_value":5000000,"total_sales":"18700000","total_revenue":"21200000","milk_sales":18000000,"other_product_sales":500000,"other_income":200000,"grant_income":2500000,"bank_sales":9000000,"top5_buyer_pct":"53.48","largest_buyer_pct":"26.74","total_buyers":150,"top5_buyers_sales":10000000,"largest_buyer_sales":5000000,"gov_buyer_sales":2000000,"no_govt_buyers":1,"large_private_buyer_sales":8000000,"no_private_sector_buyer":3,"small_buyer_sales":1000000,"no_small_buyer_sales":15,"avg_collection_days":55,"contract_coverage":2,"total_opex":"15730000","raw_milk_cost":13000000,"processing_cost":0,"packaging_cost":0,"transport_cost":400000,"other_processing_cost":0,"salary_expense":1200000,"admin_expense":350000,"electricity_expense":200000,"fuel_expense":150000,"repair_expense":100000,"rent_expense":80000,"other_opex":250000,"lowest_monthly_expense":400000,"annual_depreciation":400000,"amortization_amount":30000,"total_cash":"1500000","total_current_assets":"3450000","total_fixed_assets":"6850000","total_assets":"10300000","cash_hand":200000,"bank_balance":1300000,"accounts_receivable":1500000,"inventory_value":300000,"prepaid_expenses":50000,"other_current_assets":100000,"land_value":4000000,"building_value":1200000,"machinery_value":800000,"vehicle_value":600000,"furniture_value":150000,"other_fixed_assets":100000,"total_current_liabilities":"3600000","total_long_term_liabilities":"4500000","total_liabilities":"8100000","accounts_payable":800000,"short_term_loan":1500000,"accrued_expenses":300000,"current_ltd":1000000,"long_term_loan":4000000,"other_ltl":500000,"total_net_worth":"2300000","paid_up_capital":1500000,"retained_earnings":500000,"reserve_fund":300000,"total_milk_sold":"1520000","avg_milk_per_farmer":"5714.29","total_milk_collected":1600000,"milk_loss":80000,"processing_loss":0,"avg_monthly_milk":133000,"lowest_monthly_milk":80000,"highest_monthly_milk":180000,"avg_inventory_value":200000,"credit_period_given_days":21,"top5_farmers_milk":640000,"highest_farmer_qty":50000,"lowest_farmer_qty":500,"total_farmers":280,"collection_days":310,"total_member_loans":3500000,"npa_member_loans":280000,"overdue_member_loans":400000,"restructured_loans_3yr":"Few Times","max_dpd_members":65,"credit_history_flag":"With few delays","cash_last_year":1500000,"cash_prev_year":1800000,"audit_observations":5,"mgmt_experience":4,"internal_control_score":"20","loan_policy_compliance":"No","vehicle_avail_pct":"Yes","storage_cold_facility":"No","quality_sop_score":"65","insurance_available":"No","digital_mis_pos":"Partial","regulatory_compliance":"Partial","climatic_risk_score":"5","credit_history_bfi":"Watch List","max_dpd_bfi":10,"meeting_frequency":"Monthly","member_info_transparency":"Sometimes","fund_usage":"Buying Milk","kyc_aml":"Sometimes","income_expense_checked":"Occasionally","right_to_information":"Sometimes beforehand","community_support_level":"Moderate","emergency_response":"Ad-hoc","customer_type":"new"} | G5: SUB-5B5DFB97-694 | H5: rejected | I5: tesT | J5: 2026-03-18T05:05:35.778Z
A6: 2026-03-18T04:37:19.814Z | B6: 46099.432 | C6: 749 | D6: B Risk | E6: Terai Milk Cooperative (Test) | F6: {"model_type":"","loan_type":"","coop_name":"Terai Milk Cooperative (Test)","years_operation":8,"office_location":"Chitwan, Bagmati","total_loan":"4500000","existing_loan":500000,"proposed_loan":4000000,"interest_rate":10,"loan_tenure":60,"installment_freq":"Monthly","primary_land_value":7000000,"total_sales":"31800000","total_revenue":"32600000","milk_sales":30000000,"other_product_sales":1500000,"other_income":300000,"grant_income":800000,"bank_sales":22000000,"top5_buyer_pct":"37.74","largest_buyer_pct":"12.58","total_buyers":300,"top5_buyers_sales":12000000,"largest_buyer_sales":4000000,"gov_buyer_sales":5000000,"no_govt_buyers":2,"large_private_buyer_sales":15000000,"no_private_sector_buyer":4,"small_buyer_sales":800000,"no_small_buyer_sales":8,"avg_collection_days":35,"contract_coverage":5,"total_opex":"23350000","raw_milk_cost":20000000,"processing_cost":0,"packaging_cost":0,"transport_cost":500000,"other_processing_cost":0,"salary_expense":1500000,"admin_expense":400000,"electricity_expense":250000,"fuel_expense":180000,"repair_expense":120000,"rent_expense":100000,"other_opex":300000,"lowest_monthly_expense":300000,"annual_depreciation":600000,"amortization_amount":50000,"total_cash":"3200000","total_current_assets":"4830000","total_fixed_assets":"11050000","total_assets":"15880000","cash_hand":300000,"bank_balance":2900000,"accounts_receivable":1000000,"inventory_value":400000,"prepaid_expenses":80000,"other_current_assets":150000,"land_value":6000000,"building_value":2000000,"machinery_value":1500000,"vehicle_value":1200000,"furniture_value":200000,"other_fixed_assets":150000,"total_current_liabilities":"1950000","total_long_term_liabilities":"3200000","total_liabilities":"5150000","accounts_payable":500000,"short_term_loan":500000,"accrued_expenses":150000,"current_ltd":800000,"long_term_loan":3200000,"other_ltl":0,"total_net_worth":"6000000","paid_up_capital":3000000,"retained_earnings":2000000,"reserve_fund":1000000,"total_milk_sold":"2730000","avg_milk_per_farmer":"6222.22","total_milk_collected":2800000,"milk_loss":70000,"processing_loss":0,"avg_monthly_milk":233000,"lowest_monthly_milk":180000,"highest_monthly_milk":290000,"avg_inventory_value":300000,"credit_period_given_days":10,"top5_farmers_milk":560000,"highest_farmer_qty":70000,"lowest_farmer_qty":800,"total_farmers":450,"collection_days":340,"total_member_loans":5000000,"npa_member_loans":150000,"overdue_member_loans":200000,"restructured_loans_3yr":"Few Times","max_dpd_members":35,"credit_history_flag":"With few delays","cash_last_year":3200000,"cash_prev_year":2800000,"audit_observations":2,"mgmt_experience":7,"internal_control_score":"65","loan_policy_compliance":"Yes","vehicle_avail_pct":"Yes","storage_cold_facility":"Yes","quality_sop_score":"65","insurance_available":"Yes","digital_mis_pos":"Partial","regulatory_compliance":"Partial","climatic_risk_score":"5","credit_history_bfi":"Pass","max_dpd_bfi":0,"meeting_frequency":"Monthly","member_info_transparency":"Mostly","fund_usage":"Buying Milk","kyc_aml":"Mostly","income_expense_checked":"Regularly","right_to_information":"Mostly Beforehand","community_support_level":"Moderate","emergency_response":"Ad-hoc","customer_type":"new"} | G6: SUB-1482A024-26D | H6: conditional | I6: test | J6: 2026-03-18T05:05:13.624Z
A7: 2026-03-18T05:08:06.634Z | B7: 46099.454 | C7: 749 | D7: B Risk | E7: Terai Milk Cooperative (Test) | F7: {"model_type":"","loan_type":"","coop_name":"Terai Milk Cooperative (Test)","years_operation":8,"office_location":"Chitwan, Bagmati","total_loan":"4500000","existing_loan":500000,"proposed_loan":4000000,"interest_rate":10,"loan_tenure":60,"installment_freq":"Monthly","primary_land_value":7000000,"total_sales":"31800000","total_revenue":"32600000","milk_sales":30000000,"other_product_sales":1500000,"other_income":300000,"grant_income":800000,"bank_sales":22000000,"top5_buyer_pct":"37.74","largest_buyer_pct":"12.58","total_buyers":300,"top5_buyers_sales":12000000,"largest_buyer_sales":4000000,"gov_buyer_sales":5000000,"no_govt_buyers":2,"large_private_buyer_sales":15000000,"no_private_sector_buyer":4,"small_buyer_sales":800000,"no_small_buyer_sales":8,"avg_collection_days":35,"contract_coverage":5,"total_opex":"23350000","raw_milk_cost":20000000,"processing_cost":0,"packaging_cost":0,"transport_cost":500000,"other_processing_cost":0,"salary_expense":1500000,"admin_expense":400000,"electricity_expense":250000,"fuel_expense":180000,"repair_expense":120000,"rent_expense":100000,"other_opex":300000,"lowest_monthly_expense":300000,"annual_depreciation":600000,"amortization_amount":50000,"total_cash":"3200000","total_current_assets":"4830000","total_fixed_assets":"11050000","total_assets":"15880000","cash_hand":300000,"bank_balance":2900000,"accounts_receivable":1000000,"inventory_value":400000,"prepaid_expenses":80000,"other_current_assets":150000,"land_value":6000000,"building_value":2000000,"machinery_value":1500000,"vehicle_value":1200000,"furniture_value":200000,"other_fixed_assets":150000,"total_current_liabilities":"1950000","total_long_term_liabilities":"3200000","total_liabilities":"5150000","accounts_payable":500000,"short_term_loan":500000,"accrued_expenses":150000,"current_ltd":800000,"long_term_loan":3200000,"other_ltl":0,"total_net_worth":"6000000","paid_up_capital":3000000,"retained_earnings":2000000,"reserve_fund":1000000,"total_milk_sold":"2730000","avg_milk_per_farmer":"6222.22","total_milk_collected":2800000,"milk_loss":70000,"processing_loss":0,"avg_monthly_milk":233000,"lowest_monthly_milk":180000,"highest_monthly_milk":290000,"avg_inventory_value":300000,"credit_period_given_days":10,"top5_farmers_milk":560000,"highest_farmer_qty":70000,"lowest_farmer_qty":800,"total_farmers":450,"collection_days":340,"total_member_loans":5000000,"npa_member_loans":150000,"overdue_member_loans":200000,"restructured_loans_3yr":"Few Times","max_dpd_members":35,"credit_history_flag":"With few delays","cash_last_year":3200000,"cash_prev_year":2800000,"audit_observations":2,"mgmt_experience":7,"internal_control_score":"65","loan_policy_compliance":"Yes","vehicle_avail_pct":"Yes","storage_cold_facility":"Yes","quality_sop_score":"65","insurance_available":"Yes","digital_mis_pos":"Partial","regulatory_compliance":"Partial","climatic_risk_score":"5","credit_history_bfi":"Pass","max_dpd_bfi":0,"meeting_frequency":"Monthly","member_info_transparency":"Mostly","fund_usage":"Buying Milk","kyc_aml":"Mostly","income_expense_checked":"Regularly","right_to_information":"Mostly Beforehand","community_support_level":"Moderate","emergency_response":"Ad-hoc","customer_type":"new"} | G7: SUB-3ED24871-3F0 | H7: pending
A8: 2026-03-18T05:23:51.302Z | B8: 46099.464 | C8: 900 | D8: A Risk | E8: Himalayan Dairy Cooperative (Test) | F8: {"model_type":"","loan_type":"","coop_name":"Himalayan Dairy Cooperative (Test)","years_operation":15,"office_location":"Lalitpur, Bagmati","total_loan":"3000000","existing_loan":0,"proposed_loan":3000000,"interest_rate":9,"loan_tenure":60,"installment_freq":"Monthly","primary_land_value":9000000,"total_sales":"45500000","total_revenue":"45700000","milk_sales":42000000,"other_product_sales":3000000,"other_income":500000,"grant_income":200000,"bank_sales":38000000,"top5_buyer_pct":"21.98","largest_buyer_pct":"5.49","total_buyers":500,"top5_buyers_sales":10000000,"largest_buyer_sales":2500000,"gov_buyer_sales":8000000,"no_govt_buyers":3,"large_private_buyer_sales":20000000,"no_private_sector_buyer":5,"small_buyer_sales":500000,"no_small_buyer_sales":10,"avg_collection_days":20,"contract_coverage":8,"total_opex":"32050000","raw_milk_cost":28000000,"processing_cost":0,"packaging_cost":0,"transport_cost":600000,"other_processing_cost":0,"salary_expense":2000000,"admin_expense":500000,"electricity_expense":300000,"fuel_expense":200000,"repair_expense":150000,"rent_expense":100000,"other_opex":200000,"lowest_monthly_expense":250000,"annual_depreciation":800000,"amortization_amount":100000,"total_cash":"5500000","total_current_assets":"7200000","total_fixed_assets":"15500000","total_assets":"22700000","cash_hand":500000,"bank_balance":5000000,"accounts_receivable":800000,"inventory_value":600000,"prepaid_expenses":100000,"other_current_assets":200000,"land_value":8000000,"building_value":3000000,"machinery_value":2500000,"vehicle_value":1500000,"furniture_value":300000,"other_fixed_assets":200000,"total_current_liabilities":"1000000","total_long_term_liabilities":"2400000","total_liabilities":"3400000","accounts_payable":300000,"short_term_loan":0,"accrued_expenses":100000,"current_ltd":600000,"long_term_loan":2400000,"other_ltl":0,"total_net_worth":"11000000","paid_up_capital":5000000,"retained_earnings":4000000,"reserve_fund":2000000,"total_milk_sold":"4158000","avg_milk_per_farmer":"6000","total_milk_collected":4200000,"milk_loss":42000,"processing_loss":0,"avg_monthly_milk":350000,"lowest_monthly_milk":310000,"highest_monthly_milk":420000,"avg_inventory_value":400000,"credit_period_given_days":7,"top5_farmers_milk":500000,"highest_farmer_qty":90000,"lowest_farmer_qty":1000,"total_farmers":700,"collection_days":355,"total_member_loans":8000000,"npa_member_loans":80000,"overdue_member_loans":120000,"restructured_loans_3yr":"None","max_dpd_members":10,"credit_history_flag":"Timely","cash_last_year":5500000,"cash_prev_year":4200000,"audit_observations":0,"mgmt_experience":12,"internal_control_score":"85","loan_policy_compliance":"Yes","vehicle_avail_pct":"Yes","storage_cold_facility":"Yes","quality_sop_score":"85","insurance_available":"Yes","digital_mis_pos":"Yes","regulatory_compliance":"Yes","climatic_risk_score":"2","credit_history_bfi":"Pass","max_dpd_bfi":0,"meeting_frequency":"Weekly","member_info_transparency":"Always","fund_usage":"Buying Milk","kyc_aml":"Easily Found","income_expense_checked":"Regularly","right_to_information":"Always Beforehand","community_support_level":"Significant","emergency_response":"Proper Plan","customer_type":"existing"} | G8: SUB-5BDCEB7B-D20 | H8: pending
A9: 2026-03-18T05:39:41.105Z | B9: 46099.476 | C9: 614 | D9: C Risk | E9: Manual testing | F9: {"model_type":"","loan_type":"","coop_name":"Manual testing","years_operation":5,"office_location":"Chitwan, Bagmati","total_loan":"148530482","existing_loan":148484848,"proposed_loan":45634,"interest_rate":45,"loan_tenure":53,"installment_freq":"Quarterly","primary_land_value":453453453,"total_sales":"1360360359","total_revenue":"1360813812","milk_sales":453453453,"other_product_sales":453453453,"other_income":453453453,"grant_income":453453,"bank_sales":453453453453,"top5_buyer_pct":"33333.33","largest_buyer_pct":"39.95","total_buyers":453,"top5_buyers_sales":453453453453,"largest_buyer_sales":543453453,"gov_buyer_sales":453453453,"no_govt_buyers":4,"large_private_buyer_sales":453453453,"no_private_sector_buyer":4,"small_buyer_sales":453453453,"no_small_buyer_sales":54,"avg_collection_days":45,"contract_coverage":5,"total_opex":"11999162158","raw_milk_cost":4563453453,"processing_cost":0,"packaging_cost":0,"transport_cost":4534534534,"other_processing_cost":0,"salary_expense":543453453,"admin_expense":543453453,"electricity_expense":453453453,"fuel_expense":453453453,"repair_expense":453453453,"rent_expense":453453,"other_opex":453453453,"lowest_monthly_expense":543453453,"annual_depreciation":453453,"amortization_amount":4,"total_cash":"45796887","total_current_assets":"141495362","total_fixed_assets":"5751094482","total_assets":"5892589844","cash_hand":453453,"bank_balance":45343434,"accounts_receivable":4554354,"inventory_value":45345345,"prepaid_expenses":453433,"other_current_assets":45345343,"land_value":453453453,"building_value":45343435,"machinery_value":4345345344,"vehicle_value":453453453,"furniture_value":453453453,"other_fixed_assets":45344,"total_current_liabilities":"1903813812","total_long_term_liabilities":"453453457","total_liabilities":"2357267269","accounts_payable":453453453,"short_term_loan":453453453,"accrued_expenses":543453453,"current_ltd":453453453,"long_term_loan":453453453,"other_ltl":4,"total_net_worth":"1360360359","paid_up_capital":453453453,"retained_earnings":453453453,"reserve_fund":453453453,"total_milk_sold":"400000000","avg_milk_per_farmer":"1001001","total_milk_collected":453453453,"milk_loss":53453453,"processing_loss":0,"avg_monthly_milk":453453435,"lowest_monthly_milk":45345343,"highest_monthly_milk":453453453,"avg_inventory_value":453453453,"credit_period_given_days":45,"top5_farmers_milk":453453453,"highest_farmer_qty":453453453,"lowest_farmer_qty":453,"total_farmers":453,"collection_days":453,"total_member_loans":45343435545,"npa_member_loans":5434534,"overdue_member_loans":453453453,"restructured_loans_3yr":"Few Times","max_dpd_members":45,"credit_history_flag":"With few delays","cash_last_year":453453453,"cash_prev_year":453453453,"audit_observations":5,"mgmt_experience":8,"internal_control_score":"65","loan_policy_compliance":"Yes","vehicle_avail_pct":"Yes","storage_cold_facility":"Yes","quality_sop_score":"85","insurance_available":"Yes","digital_mis_pos":"Partial","regulatory_compliance":"Partial","climatic_risk_score":"5","credit_history_bfi":"Substandard","max_dpd_bfi":4,"meeting_frequency":"Monthly","member_info_transparency":"Sometimes","fund_usage":"Processing","kyc_aml":"Sometimes","income_expense_checked":"Occasionally","right_to_information":"Mostly Beforehand","community_support_level":"Moderate","emergency_response":"Ad-hoc","customer_type":"new"} | G9: SUB-4E8ECBC2-948 | H9: pending
A10: 2026-03-18T05:47:44.817Z | B10: 46099.481 | C10: 900 | D10: A Risk | E10: Himalayan Dairy Cooperative (Test) | F10: {"model_type":"","loan_type":"","coop_name":"Himalayan Dairy Cooperative (Test)","years_operation":15,"office_location":"Lalitpur, Bagmati","total_loan":"3000000","existing_loan":0,"proposed_loan":3000000,"interest_rate":9,"loan_tenure":60,"installment_freq":"Monthly","primary_land_value":9000000,"total_sales":"45500000","total_revenue":"45700000","milk_sales":42000000,"other_product_sales":3000000,"other_income":500000,"grant_income":200000,"bank_sales":38000000,"top5_buyer_pct":"21.98","largest_buyer_pct":"5.49","total_buyers":500,"top5_buyers_sales":10000000,"largest_buyer_sales":2500000,"gov_buyer_sales":8000000,"no_govt_buyers":3,"large_private_buyer_sales":20000000,"no_private_sector_buyer":5,"small_buyer_sales":500000,"no_small_buyer_sales":10,"avg_collection_days":20,"contract_coverage":8,"total_opex":"32050000","raw_milk_cost":28000000,"processing_cost":0,"packaging_cost":0,"transport_cost":600000,"other_processing_cost":0,"salary_expense":2000000,"admin_expense":500000,"electricity_expense":300000,"fuel_expense":200000,"repair_expense":150000,"rent_expense":100000,"other_opex":200000,"lowest_monthly_expense":250000,"annual_depreciation":800000,"amortization_amount":100000,"total_cash":"5500000","total_current_assets":"7200000","total_fixed_assets":"15500000","total_assets":"22700000","cash_hand":500000,"bank_balance":5000000,"accounts_receivable":800000,"inventory_value":600000,"prepaid_expenses":100000,"other_current_assets":200000,"land_value":8000000,"building_value":3000000,"machinery_value":2500000,"vehicle_value":1500000,"furniture_value":300000,"other_fixed_assets":200000,"total_current_liabilities":"1000000","total_long_term_liabilities":"2400000","total_liabilities":"3400000","accounts_payable":300000,"short_term_loan":0,"accrued_expenses":100000,"current_ltd":600000,"long_term_loan":2400000,"other_ltl":0,"total_net_worth":"11000000","paid_up_capital":5000000,"retained_earnings":4000000,"reserve_fund":2000000,"total_milk_sold":"4158000","avg_milk_per_farmer":"6000","total_milk_collected":4200000,"milk_loss":42000,"processing_loss":0,"avg_monthly_milk":350000,"lowest_monthly_milk":310000,"highest_monthly_milk":420000,"avg_inventory_value":400000,"credit_period_given_days":7,"top5_farmers_milk":500000,"highest_farmer_qty":90000,"lowest_farmer_qty":1000,"total_farmers":700,"collection_days":355,"total_member_loans":8000000,"npa_member_loans":80000,"overdue_member_loans":120000,"restructured_loans_3yr":"None","max_dpd_members":10,"credit_history_flag":"Timely","cash_last_year":5500000,"cash_prev_year":4200000,"audit_observations":0,"mgmt_experience":12,"internal_control_score":"85","loan_policy_compliance":"Yes","vehicle_avail_pct":"Yes","storage_cold_facility":"Yes","quality_sop_score":"85","insurance_available":"Yes","digital_mis_pos":"Yes","regulatory_compliance":"Yes","climatic_risk_score":"2","credit_history_bfi":"Pass","max_dpd_bfi":0,"meeting_frequency":"Weekly","member_info_transparency":"Always","fund_usage":"Buying Milk","kyc_aml":"Easily Found","income_expense_checked":"Regularly","right_to_information":"Always Beforehand","community_support_level":"Significant","emergency_response":"Proper Plan","customer_type":"existing"} | G10: SUB-42357BCB-832 | H10: pending

Sheet Users
A1: Email | B1: Password | C1: Role | D1: Status | E1: time_logged_in | F1: time_logged_out
A2: test@admin.com | B2: 3b612c75a7b5048a435fb6ec81e52ff92d6d795a8b5a9c17070f6a63c97a53b2 | C2: admin | D2: active | E2: 46099.465 | F2: 46099.337
A3: test | B3: 3b612c75a7b5048a435fb6ec81e52ff92d6d795a8b5a9c17070f6a63c97a53b2 | C3: admin | D3: active | E3: 46099.476 | F3: 46098.439

Sheet Submission
A1: S.n | B1: coop_name | C1: time_stamp | D1: Result
